2022-04-09 12:52:30,667 INFO    MainThread:14515 [internal.py:wandb_internal():92] W&B internal server running at pid: 14515, started at: 2022-04-09 12:52:30.667231
2022-04-09 12:52:30,669 INFO    WriterThread:14515 [datastore.py:open_for_write():77] open: /home/zc1995/tokenlabeling_covid/wandb/run-20220409_125229-ywa22rcm/run-ywa22rcm.wandb
2022-04-09 12:52:30,671 DEBUG   SenderThread:14515 [sender.py:send():235] send: header
2022-04-09 12:52:30,671 DEBUG   SenderThread:14515 [sender.py:send():235] send: run
2022-04-09 12:52:47,642 DEBUG   HandlerThread:14515 [handler.py:handle_request():141] handle_request: check_version
2022-04-09 12:52:47,665 INFO    SenderThread:14515 [dir_watcher.py:__init__():169] watching files in: /home/zc1995/tokenlabeling_covid/wandb/run-20220409_125229-ywa22rcm/files
2022-04-09 12:52:47,665 INFO    SenderThread:14515 [sender.py:_start_run_threads():812] run started: ywa22rcm with start time 1649523149
2022-04-09 12:52:47,665 DEBUG   SenderThread:14515 [sender.py:send():235] send: summary
2022-04-09 12:52:47,665 INFO    SenderThread:14515 [sender.py:_save_file():947] saving file wandb-summary.json with policy end
2022-04-09 12:52:47,666 DEBUG   SenderThread:14515 [sender.py:send_request():249] send_request: check_version
2022-04-09 12:52:48,666 INFO    Thread-7  :14515 [dir_watcher.py:_on_file_created():217] file/dir created: /home/zc1995/tokenlabeling_covid/wandb/run-20220409_125229-ywa22rcm/files/wandb-summary.json
2022-04-09 12:52:49,569 DEBUG   HandlerThread:14515 [handler.py:handle_request():141] handle_request: run_start
2022-04-09 12:52:49,597 DEBUG   HandlerThread:14515 [meta.py:__init__():37] meta init
2022-04-09 12:52:49,597 DEBUG   HandlerThread:14515 [meta.py:__init__():51] meta init done
2022-04-09 12:52:49,597 DEBUG   HandlerThread:14515 [meta.py:probe():211] probe
2022-04-09 12:52:49,606 DEBUG   HandlerThread:14515 [meta.py:_setup_git():201] setup git
2022-04-09 12:52:49,622 DEBUG   HandlerThread:14515 [meta.py:_setup_git():208] setup git done
2022-04-09 12:52:49,622 DEBUG   HandlerThread:14515 [meta.py:_save_pip():55] save pip
2022-04-09 12:52:49,623 DEBUG   HandlerThread:14515 [meta.py:_save_pip():69] save pip done
2022-04-09 12:52:49,623 DEBUG   HandlerThread:14515 [meta.py:probe():249] probe done
2022-04-09 12:52:49,629 DEBUG   SenderThread:14515 [sender.py:send():235] send: files
2022-04-09 12:52:49,629 INFO    SenderThread:14515 [sender.py:_save_file():947] saving file wandb-metadata.json with policy now
2022-04-09 12:52:49,632 DEBUG   HandlerThread:14515 [handler.py:handle_request():141] handle_request: stop_status
2022-04-09 12:52:49,632 DEBUG   SenderThread:14515 [sender.py:send_request():249] send_request: stop_status
2022-04-09 12:52:49,666 INFO    Thread-7  :14515 [dir_watcher.py:_on_file_created():217] file/dir created: /home/zc1995/tokenlabeling_covid/wandb/run-20220409_125229-ywa22rcm/files/requirements.txt
2022-04-09 12:52:49,666 INFO    Thread-7  :14515 [dir_watcher.py:_on_file_created():217] file/dir created: /home/zc1995/tokenlabeling_covid/wandb/run-20220409_125229-ywa22rcm/files/wandb-metadata.json
2022-04-09 12:52:49,666 INFO    Thread-7  :14515 [dir_watcher.py:_on_file_created():217] file/dir created: /home/zc1995/tokenlabeling_covid/wandb/run-20220409_125229-ywa22rcm/files/output.log
2022-04-09 12:52:51,666 INFO    Thread-7  :14515 [dir_watcher.py:_on_file_modified():230] file/dir modified: /home/zc1995/tokenlabeling_covid/wandb/run-20220409_125229-ywa22rcm/files/output.log
2022-04-09 12:52:53,667 INFO    Thread-7  :14515 [dir_watcher.py:_on_file_modified():230] file/dir modified: /home/zc1995/tokenlabeling_covid/wandb/run-20220409_125229-ywa22rcm/files/output.log
2022-04-09 12:52:54,788 INFO    Thread-11 :14515 [upload_job.py:push():137] Uploaded file /tmp/tmppyuqsgohwandb/19ppvr3s-wandb-metadata.json
2022-04-09 12:52:55,608 DEBUG   SenderThread:14515 [sender.py:send():235] send: telemetry
2022-04-09 12:52:59,669 INFO    Thread-7  :14515 [dir_watcher.py:_on_file_modified():230] file/dir modified: /home/zc1995/tokenlabeling_covid/wandb/run-20220409_125229-ywa22rcm/files/output.log
2022-04-09 12:53:09,882 DEBUG   HandlerThread:14515 [handler.py:handle_request():141] handle_request: stop_status
2022-04-09 12:53:43,156 DEBUG   HandlerThread:14515 [handler.py:handle_request():141] handle_request: stop_status
2022-04-09 12:54:18,134 DEBUG   HandlerThread:14515 [handler.py:handle_request():141] handle_request: stop_status
2022-04-09 12:54:29,384 DEBUG   HandlerThread:14515 [handler.py:handle_request():141] handle_request: stop_status
2022-04-09 12:54:47,948 ERROR   SenderThread:14515 [retry.py:__call__():126] Retry attempt failed:
Traceback (most recent call last):
  File "/usr/lib/python3/dist-packages/urllib3/contrib/pyopenssl.py", line 485, in wrap_socket
    cnx.do_handshake()
  File "/usr/lib/python3/dist-packages/OpenSSL/SSL.py", line 1915, in do_handshake
    self._raise_ssl_error(self._ssl, result)
  File "/usr/lib/python3/dist-packages/OpenSSL/SSL.py", line 1622, in _raise_ssl_error
    raise WantReadError()
OpenSSL.SSL.WantReadError

During handling of the above exception, another exception occurred:

Traceback (most recent call last):
  File "/usr/lib/python3/dist-packages/urllib3/connectionpool.py", line 376, in _make_request
    self._validate_conn(conn)
  File "/usr/lib/python3/dist-packages/urllib3/connectionpool.py", line 996, in _validate_conn
    conn.connect()
  File "/usr/lib/python3/dist-packages/urllib3/connection.py", line 366, in connect
    self.sock = ssl_wrap_socket(
  File "/usr/lib/python3/dist-packages/urllib3/util/ssl_.py", line 370, in ssl_wrap_socket
    return context.wrap_socket(sock, server_hostname=server_hostname)
  File "/usr/lib/python3/dist-packages/urllib3/contrib/pyopenssl.py", line 488, in wrap_socket
    raise timeout("select timed out")
socket.timeout: select timed out

During handling of the above exception, another exception occurred:

Traceback (most recent call last):
  File "/usr/lib/python3/dist-packages/requests/adapters.py", line 439, in send
    resp = conn.urlopen(
  File "/usr/lib/python3/dist-packages/urllib3/connectionpool.py", line 719, in urlopen
    retries = retries.increment(
  File "/usr/lib/python3/dist-packages/urllib3/util/retry.py", line 400, in increment
    raise six.reraise(type(error), error, _stacktrace)
  File "/usr/lib/python3/dist-packages/six.py", line 703, in reraise
    raise value
  File "/usr/lib/python3/dist-packages/urllib3/connectionpool.py", line 665, in urlopen
    httplib_response = self._make_request(
  File "/usr/lib/python3/dist-packages/urllib3/connectionpool.py", line 379, in _make_request
    self._raise_timeout(err=e, url=url, timeout_value=conn.timeout)
  File "/usr/lib/python3/dist-packages/urllib3/connectionpool.py", line 330, in _raise_timeout
    raise ReadTimeoutError(
urllib3.exceptions.ReadTimeoutError: HTTPSConnectionPool(host='api.wandb.ai', port=443): Read timed out. (read timeout=10)

During handling of the above exception, another exception occurred:

Traceback (most recent call last):
  File "/home/zc1995/.local/lib/python3.8/site-packages/wandb/sdk/lib/retry.py", line 102, in __call__
    result = self._call_fn(*args, **kwargs)
  File "/home/zc1995/.local/lib/python3.8/site-packages/wandb/sdk/internal/internal_api.py", line 141, in execute
    return self.client.execute(*args, **kwargs)
  File "/home/zc1995/.local/lib/python3.8/site-packages/wandb/vendor/gql-0.2.0/wandb_gql/client.py", line 52, in execute
    result = self._get_result(document, *args, **kwargs)
  File "/home/zc1995/.local/lib/python3.8/site-packages/wandb/vendor/gql-0.2.0/wandb_gql/client.py", line 60, in _get_result
    return self.transport.execute(document, *args, **kwargs)
  File "/home/zc1995/.local/lib/python3.8/site-packages/wandb/vendor/gql-0.2.0/wandb_gql/transport/requests.py", line 38, in execute
    request = requests.post(self.url, **post_args)
  File "/usr/lib/python3/dist-packages/requests/api.py", line 116, in post
    return request('post', url, data=data, json=json, **kwargs)
  File "/usr/lib/python3/dist-packages/requests/api.py", line 60, in request
    return session.request(method=method, url=url, **kwargs)
  File "/usr/lib/python3/dist-packages/requests/sessions.py", line 533, in request
    resp = self.send(prep, **send_kwargs)
  File "/usr/lib/python3/dist-packages/requests/sessions.py", line 646, in send
    r = adapter.send(request, **kwargs)
  File "/usr/lib/python3/dist-packages/requests/adapters.py", line 529, in send
    raise ReadTimeout(e, request=request)
requests.exceptions.ReadTimeout: HTTPSConnectionPool(host='api.wandb.ai', port=443): Read timed out. (read timeout=10)
2022-04-09 12:54:52,565 DEBUG   HandlerThread:14515 [handler.py:handle_request():141] handle_request: stop_status
2022-04-09 12:55:42,229 DEBUG   HandlerThread:14515 [handler.py:handle_request():141] handle_request: stop_status
2022-04-09 12:55:45,059 DEBUG   HandlerThread:14515 [handler.py:handle_request():141] handle_request: stop_status
2022-04-09 12:56:20,069 DEBUG   HandlerThread:14515 [handler.py:handle_request():141] handle_request: stop_status
2022-04-09 12:56:51,612 DEBUG   HandlerThread:14515 [handler.py:handle_request():141] handle_request: stop_status
2022-04-09 12:57:06,224 DEBUG   HandlerThread:14515 [handler.py:handle_request():141] handle_request: stop_status
2022-04-09 12:57:30,744 DEBUG   HandlerThread:14515 [handler.py:handle_request():141] handle_request: stop_status
2022-04-09 12:57:44,822 WARNING MainThread:14515 [internal.py:wandb_internal():155] Internal process interrupt: 1
2022-04-09 12:57:44,891 DEBUG   HandlerThread:14515 [handler.py:handle_request():141] handle_request: stop_status
